<?xml version="1.0"?>
<robot name="rover" xmlns:xacro="http://www.ros.org/wiki/xacro">

    <!--  Define Materials -->
    <material name="metallic_gray">
        <color rgba="0.3 0.3 0.3 1.0"/>
    </material>
    <material name="chrome_silver">
        <color rgba="0.8 0.8 0.9 1.0"/>
    </material>
    <material name="holo_purple">
        <color rgba="0.6 0.2 0.8 1.0"/>
    </material>
    <material name="tire_tread">
        <color rgba="0.1 0.1 0.1 1.0"/>
    </material>

    <!--  Base Link (Main Body) -->
    <link name="base_link">
        <visual>
            <geometry>
                <box size="0.23 0.15 0.10"/>  <!-- 23cm x 15cm x 10cm -->
            </geometry>
            <material name="holo_purple"/>
        </visual>
        <collision>
            <geometry>
                <box size="0.23 0.15 0.10"/>
            </geometry>
        </collision>
        <inertial>
            <mass value="2.0"/>
            <origin xyz="0 0 0"/>
            <inertia ixx="0.02" iyy="0.02" izz="0.02" ixy="0" ixz="0" iyz="0"/>
        </inertial>
    </link>

    <!-- Front Left Wheel -->
    <link name="front_left_wheel">
        <!--Outer Tire -->
        <visual>
            <geometry>
                <cylinder length="0.02" radius="0.03"/>
            </geometry>
            <material name="tire_tread"/>
        </visual>

        <!--  Chrome Rim -->
        <visual>
            <geometry>
                <cylinder length="0.005" radius="0.03"/>
            </geometry>
            <material name="chrome_silver"/>
        </visual>

        <!--  Inner Core -->
        <visual>
            <geometry>
                <cylinder length="0.01" radius="0.025"/>
            </geometry>
            <material name="metallic_gray"/>
        </visual>
    </link>

    <!--  Front Right Wheel -->
    <link name="front_right_wheel">
        <visual>
            <geometry>
                <cylinder length="0.02" radius="0.03"/>
            </geometry>
            <material name="tire_tread"/>
        </visual>
        <visual>
            <geometry>
                <cylinder length="0.005" radius="0.03"/>
            </geometry>
            <material name="chrome_silver"/>
        </visual>
        <visual>
            <geometry>
                <cylinder length="0.01" radius="0.025"/>
            </geometry>
            <material name="metallic_gray"/>
        </visual>
    </link>

    <!--  Rear Left Wheel -->
    <link name="rear_left_wheel">
        <visual>
            <geometry>
                <cylinder length="0.02" radius="0.03"/>
            </geometry>
            <material name="tire_tread"/>
        </visual>
        <visual>
            <geometry>
                <cylinder length="0.005" radius="0.03"/>
            </geometry>
            <material name="chrome_silver"/>
        </visual>
        <visual>
            <geometry>
                <cylinder length="0.01" radius="0.025"/>
            </geometry>
            <material name="metallic_gray"/>
        </visual>
    </link>

    <!--  Rear Right Wheel -->
    <link name="rear_right_wheel">
        <visual>
            <geometry>
                <cylinder length="0.02" radius="0.03"/>
            </geometry>
            <material name="tire_tread"/>
        </visual>
        <visual>
            <geometry>
                <cylinder length="0.005" radius="0.03"/>
            </geometry>
            <material name="chrome_silver"/>
        </visual>
        <visual>
            <geometry>
                <cylinder length="0.01" radius="0.025"/>
            </geometry>
            <material name="metallic_gray"/>
        </visual>
    </link>

    <!--  Joints -->

    <!-- Front Left Wheel Joint -->
    <joint name="front_left_wheel_joint" type="continuous">
        <parent link="base_link"/>
        <child link="front_left_wheel"/>
        <origin xyz="-0.06 0.09 -0.055" rpy="1.57 0 0"/>
        <axis xyz="0 0 1"/>
    </joint>

    <!-- Front Right Wheel Joint -->
    <joint name="front_right_wheel_joint" type="continuous">
        <parent link="base_link"/>
        <child link="front_right_wheel"/>
        <origin xyz="0.06 0.09 -0.055" rpy="1.57 0 0"/>
        <axis xyz="0 0 1"/>
    </joint>

    <!-- Rear Left Wheel Joint -->
    <joint name="rear_left_wheel_joint" type="continuous">
        <parent link="base_link"/>
        <child link="rear_left_wheel"/>
        <origin xyz="-0.06 -0.09 -0.055" rpy="1.57 0 0"/>
        <axis xyz="0 0 1"/>
    </joint>

    <!-- Rear Right Wheel Joint -->
    <joint name="rear_right_wheel_joint" type="continuous">
        <parent link="base_link"/>
        <child link="rear_right_wheel"/>
        <origin xyz="0.06 -0.09 -0.055" rpy="1.57 0 0"/>
        <axis xyz="0 0 1"/>
    </joint>

</robot>



